Traceback (most recent call last):
  File "C:\Users\sofmo\miniconda3\Lib\site-packages\jupyter_cache\executors\utils.py", line 58, in single_nb_execution
    executenb(
  File "C:\Users\sofmo\miniconda3\Lib\site-packages\nbclient\client.py", line 1314, in execute
    return NotebookClient(nb=nb, resources=resources, km=km, **kwargs).execute()
           ^^^^^^^^^^^^^^^^^^^^^^^^^^^^^^^^^^^^^^^^^^^^^^^^^^^^^^^^^^^^^^^^^^^^^
  File "C:\Users\sofmo\miniconda3\Lib\site-packages\jupyter_core\utils\__init__.py", line 165, in wrapped
    return loop.run_until_complete(inner)
           ^^^^^^^^^^^^^^^^^^^^^^^^^^^^^^
  File "C:\Users\sofmo\miniconda3\Lib\asyncio\base_events.py", line 687, in run_until_complete
    return future.result()
           ^^^^^^^^^^^^^^^
  File "C:\Users\sofmo\miniconda3\Lib\site-packages\nbclient\client.py", line 709, in async_execute
    await self.async_execute_cell(
  File "C:\Users\sofmo\miniconda3\Lib\site-packages\nbclient\client.py", line 1062, in async_execute_cell
    await self._check_raise_for_error(cell, cell_index, exec_reply)
  File "C:\Users\sofmo\miniconda3\Lib\site-packages\nbclient\client.py", line 918, in _check_raise_for_error
    raise CellExecutionError.from_cell_and_msg(cell, exec_reply_content)
nbclient.exceptions.CellExecutionError: An error occurred while executing the following cell:
------------------
import yfinance as yf
import pandas as pd
from IPython.display import display
import numpy as np
import matplotlib.pyplot as plt
import seaborn as sns
import missingno as msno
from statsmodels.stats.diagnostic import acorr_ljungbox
from statsmodels.tsa.seasonal import seasonal_decompose
from statsmodels.tsa.stattools import adfuller
from statsmodels.graphics.tsaplots import plot_acf, plot_pacf
from statsmodels.tsa.arima.model import ARIMA
from scipy.stats import jarque_bera
from scipy.stats import shapiro
import statsmodels.api as sm
import statsmodels.tsa.api as smtsa
from scipy.stats import kstest
import requests
import io
from statsmodels.tsa import stattools
from statsmodels.tsa import seasonal
warnings.simplefilter(action="ignore", category=FutureWarning)
from sklearn.model_selection import TimeSeriesSplit
from sklearn.metrics import mean_squared_error

import warnings
warnings.filterwarnings('ignore')
------------------


[1;31m------------------------------------------------------------------------[0m
[1;31mModuleNotFoundError[0m                    Traceback (most recent call last)
Cell [1;32mIn[1], line 1[0m
[1;32m----> 1[0m [38;5;28;01mimport[39;00m [38;5;21;01myfinance[39;00m [38;5;28;01mas[39;00m [38;5;21;01myf[39;00m
[0;32m      2[0m [38;5;28;01mimport[39;00m [38;5;21;01mpandas[39;00m [38;5;28;01mas[39;00m [38;5;21;01mpd[39;00m
[0;32m      3[0m [38;5;28;01mfrom[39;00m [38;5;21;01mIPython[39;00m[38;5;21;01m.[39;00m[38;5;21;01mdisplay[39;00m [38;5;28;01mimport[39;00m display

[1;31mModuleNotFoundError[0m: No module named 'yfinance'

